Workbook
Name Picks: #REF!
Name Slicer_Period: #N/A
Name Slicer_Period11: #N/A
Name Slicer_Regular__Playoffs: #N/A
Name Slicer_Regular__Playoffs1: #N/A
Name Slicer_Team: #N/A
Name Slicer_Team1: #N/A
Name Slicer_Team11: #N/A
Name Slicer_Team12: #N/A
Name Slicer_vs_Opponent1: #N/A
Name Slicer_vs_Opponent11: #N/A
Name Slicer_vs_Opponent12: #N/A
Name Slicer_Year: #N/A
Name Slicer_Year1: #N/A
Name Slicer_Year11: #N/A
Name Slicer_Year2: #N/A

Sheet Playoffs
A2: Regular/ Playoffs | B2: Playoffs
A4: Row Labels | B4: Wins | C4: Ties | D4: Losses | E4: Win% | F4: FGM | G4: FG% | H4: 3PM | I4: 3P% | J4: FT% | K4: PTS | L4: OREB | M4: DREB | N4: AST | O4: STL | P4: BLK | Q4: TO | R4: A/TO | S4: Sum of Match No
A5: Final
A6: Pachiana NinjaBees | B6: 7 | C6: 0 | D6: 6 | E6: 0.53846154 | F6: 216 | G6: 0.526 | H6: 41 | I6: 0.328 | J6: 0.77 | K6: 550 | L6: 41 | M6: 149 | N6: 167 | O6: 46 | P6: 24 | Q6: 61 | R6: 2.74 | S6: 181
A7: Samarina Dudenbros2 | B7: 6 | C7: 0 | D7: 7 | E7: 0.46153846 | F7: 193 | G7: 0.451 | H7: 58 | I7: 0.343 | J7: 0.898 | K7: 558 | L7: 32 | M7: 156 | N7: 155 | O7: 35 | P7: 15 | Q7: 59 | R7: 2.63 | S7: 181
A8: Semifinals
A9: The Guns | B9: 6 | C9: 0 | D9: 7 | E9: 0.46153846 | F9: 209 | G9: 0.499 | H9: 66 | I9: 0.384 | J9: 0.815 | K9: 590 | L9: 30 | M9: 134 | N9: 112 | O9: 39 | P9: 23 | Q9: 61 | R9: 1.84 | S9: 179
A10: Samarina Dudenbros2 | B10: 7 | C10: 0 | D10: 6 | E10: 0.53846154 | F10: 186 | G10: 0.52 | H10: 55 | I10: 0.426 | J10: 0.766 | K10: 509 | L10: 37 | M10: 147 | N10: 122 | O10: 30 | P10: 13 | Q10: 51 | R10: 2.39 | S10: 179
A11: LRBP PR3DATORS | B11: 6 | C11: 0 | D11: 7 | E11: 0.46153846 | F11: 239 | G11: 0.46 | H11: 61 | I11: 0.326 | J11: 0.78 | K11: 699 | L11: 38 | M11: 145 | N11: 167 | O11: 42 | P11: 17 | Q11: 87 | R11: 1.92 | S11: 180
A12: Pachiana NinjaBees | B12: 7 | C12: 0 | D12: 6 | E12: 0.53846154 | F12: 196 | G12: 0.5 | H12: 71 | I12: 0.408 | J12: 0.839 | K12: 541 | L12: 31 | M12: 129 | N12: 116 | O12: 41 | P12: 22 | Q12: 49 | R12: 2.37 | S12: 180
A13: Quarterfinals
A14: The Guns | B14: 8 | C14: 1 | D14: 4 | E14: 0.65384615 | F14: 156 | G14: 0.52 | H14: 47 | I14: 0.42 | J14: 0.884 | K14: 420 | L14: 24 | M14: 101 | N14: 102 | O14: 25 | P14: 29 | Q14: 43 | R14: 2.37 | S14: 175
A15: Karafli SaiTa | B15: 4 | C15: 1 | D15: 8 | E15: 0.34615385 | F15: 132 | G15: 0.477 | H15: 29 | I15: 0.312 | J15: 0.914 | K15: 378 | L15: 19 | M15: 94 | N15: 119 | O15: 29 | P15: 13 | Q15: 43 | R15: 2.77 | S15: 175
A16: Fighting Thaddeus | B16: 5 | C16: 0 | D16: 8 | E16: 0.38461538 | F16: 143 | G16: 0.526 | H16: 48 | I16: 0.39 | J16: 0.853 | K16: 398 | L16: 17 | M16: 81 | N16: 93 | O16: 25 | P16: 11 | Q16: 33 | R16: 2.82 | S16: 176
A17: Samarina Dudenbros2 | B17: 8 | C17: 0 | D17: 5 | E17: 0.61538462 | F17: 247 | G17: 0.501 | H17: 59 | I17: 0.341 | J17: 0.835 | K17: 725 | L17: 40 | M17: 127 | N17: 151 | O17: 45 | P17: 21 | Q17: 79 | R17: 1.91 | S17: 176
A18: Kourayo Vallecano | B18: 3 | C18: 0 | D18: 10 | E18: 0.23076923 | F18: 128 | G18: 0.457 | H18: 38 | I18: 0.369 | J18: 0.873 | K18: 349 | L18: 51 | M18: 102 | N18: 74 | O18: 18 | P18: 9 | Q18: 42 | R18: 1.76 | S18: 177
A19: Pachiana NinjaBees | B19: 10 | C19: 0 | D19: 3 | E19: 0.76923077 | F19: 157 | G19: 0.516 | H19: 44 | I19: 0.393 | J19: 0.859 | K19: 413 | L19: 42 | M19: 114 | N19: 115 | O19: 30 | P19: 20 | Q19: 53 | R19: 2.17 | S19: 177
A20: LRBP PR3DATORS | B20: 8 | C20: 0 | D20: 5 | E20: 0.61538462 | F20: 207 | G20: 0.484 | H20: 71 | I20: 0.397 | J20: 0.788 | K20: 600 | L20: 38 | M20: 149 | N20: 160 | O20: 39 | P20: 24 | Q20: 76 | R20: 2.11 | S20: 178
A21: The Bridgeburners | B21: 5 | C21: 0 | D21: 8 | E21: 0.38461538 | F21: 203 | G21: 0.518 | H21: 49 | I21: 0.34 | J21: 0.686 | K21: 525 | L21: 58 | M21: 154 | N21: 103 | O21: 28 | P21: 28 | Q21: 58 | R21: 1.78 | S21: 178
A22: 1st Round
A23: The Guns | B23: 8 | C23: 0 | D23: 5 | E23: 0.61538462 | F23: 193 | G23: 0.52 | H23: 77 | I23: 0.45 | J23: 0.897 | K23: 541 | L23: 31 | M23: 129 | N23: 110 | O23: 32 | P23: 10 | Q23: 54 | R23: 2.04 | S23: 171
A24: purple fuzzy apache pirates | B24: 5 | C24: 0 | D24: 8 | E24: 0.38461538 | F24: 186 | G24: 0.453 | H24: 46 | I24: 0.287 | J24: 0.819 | K24: 513 | L24: 53 | M24: 179 | N24: 148 | O24: 21 | P24: 16 | Q24: 65 | R24: 2.28 | S24: 171
A25: Xanthi Ducks 🦆 | B25: 2 | C25: 0 | D25: 11 | E25: 0.15384615 | F25: 99 | G25: 0.409 | H25: 30 | I25: 0.263 | J25: 0.78 | K25: 267 | L25: 21 | M25: 81 | N25: 71 | O25: 27 | P25: 12 | Q25: 39 | R25: 1.82 | S25: 172
A26: Fighting Thaddeus | B26: 11 | C26: 0 | D26: 2 | E26: 0.84615385 | F26: 142 | G26: 0.436 | H26: 39 | I26: 0.328 | J26: 0.904 | K26: 426 | L26: 31 | M26: 100 | N26: 106 | O26: 21 | P26: 18 | Q26: 49 | R26: 2.16 | S26: 172
A27: The Bad Boys | B27: 5 | C27: 0 | D27: 8 | E27: 0.38461538 | F27: 205 | G27: 0.51 | H27: 51 | I27: 0.392 | J27: 0.708 | K27: 546 | L27: 36 | M27: 117 | N27: 128 | O27: 37 | P27: 17 | Q27: 59 | R27: 2.17 | S27: 173
A28: Pachiana NinjaBees | B28: 8 | C28: 0 | D28: 5 | E28: 0.61538462 | F28: 180 | G28: 0.506 | H28: 64 | I28: 0.381 | J28: 0.857 | K28: 502 | L28: 46 | M28: 146 | N28: 110 | O28: 39 | P28: 37 | Q28: 46 | R28: 2.39 | S28: 173
A29: Guruuu 🐐🐐🐐 | B29: 5 | C29: 0 | D29: 8 | E29: 0.38461538 | F29: 138 | G29: 0.452 | H29: 50 | I29: 0.36 | J29: 0.735 | K29: 412 | L29: 28 | M29: 106 | N29: 99 | O29: 40 | P29: 13 | Q29: 38 | R29: 2.61 | S29: 174
A30: LRBP PR3DATORS | B30: 8 | C30: 0 | D30: 5 | E30: 0.61538462 | F30: 221 | G30: 0.496 | H30: 47 | I30: 0.287 | J30: 0.752 | K30: 574 | L30: 41 | M30: 127 | N30: 119 | O30: 30 | P30: 23 | Q30: 78 | R30: 1.53 | S30: 174

Sheet Regular
A4: Row Labels | B4: Wins | C4: Ties | D4: Losses | E4: Win% | F4: FGM | G4: FG% | H4: 3PM | I4: 3P% | J4: FT% | K4: PTS | L4: OREB | M4: DREB | N4: AST | O4: STL | P4: BLK | Q4: TO | R4: A/TO | S4: Sum of Match No
A5: Karafli SaiTa | B5: 160 | C5: 4 | D5: 70 | E5: 0.69230769 | F5: 4166 | G5: 0.482 | H5: 1048 | I5: 0.35288889 | J5: 0.806 | K5: 11555 | L5: 636 | M5: 2716 | N5: 2768 | O5: 636 | P5: 517 | Q5: 1275 | R5: 2.2111111 | S5: 1532
A6: Kourayo Vallecano | B6: 151 | C6: 2 | D6: 81 | E6: 0.64957265 | F6: 3226 | G6: 0.47716667 | H6: 939 | I6: 0.35711111 | J6: 0.78955556 | K6: 8872 | L6: 919 | M6: 2595 | N6: 2186 | O6: 592 | P6: 297 | Q6: 973 | R6: 2.2911111 | S6: 1549
A7: The Bridgeburners | B7: 149 | C7: 5 | D7: 80 | E7: 0.6474359 | F7: 3196 | G7: 0.48605556 | H7: 889 | I7: 0.36727778 | J7: 0.77838889 | K7: 8752 | L7: 887 | M7: 2521 | N7: 2042 | O7: 590 | P7: 394 | Q7: 1032 | R7: 1.9677778 | S7: 1554
A8: Samarina Dudenbros2 | B8: 141 | C8: 1 | D8: 92 | E8: 0.60470085 | F8: 3788 | G8: 0.46194444 | H8: 1094 | I8: 0.34505556 | J8: 0.83033333 | K8: 10879 | L8: 759 | M8: 2480 | N8: 2585 | O8: 804 | P8: 304 | Q8: 1268 | R8: 2.07 | S8: 1541
A9: Fighting Thaddeus | B9: 135 | C9: 2 | D9: 97 | E9: 0.58119658 | F9: 3158 | G9: 0.46988889 | H9: 1086 | I9: 0.381 | J9: 0.83427778 | K9: 8792 | L9: 660 | M9: 2215 | N9: 2078 | O9: 469 | P9: 355 | Q9: 958 | R9: 2.1988889 | S9: 1527
A10: LRBP PR3DATORS | B10: 133 | C10: 2 | D10: 99 | E10: 0.57264957 | F10: 3643 | G10: 0.47755556 | H10: 857 | I10: 0.34155556 | J10: 0.76716667 | K10: 10336 | L10: 726 | M10: 2732 | N10: 2363 | O10: 566 | P10: 447 | Q10: 1308 | R10: 1.8116667 | S10: 1468
A11: The Bad Boys | B11: 131 | C11: 6 | D11: 97 | E11: 0.57264957 | F11: 3476 | G11: 0.48033333 | H11: 836 | I11: 0.35716667 | J11: 0.75322222 | K11: 9514 | L11: 857 | M11: 2357 | N11: 2018 | O11: 676 | P11: 393 | Q11: 1119 | R11: 1.8266667 | S11: 1548
A12: purple fuzzy apache pirates | B12: 128 | C12: 5 | D12: 101 | E12: 0.55769231 | F12: 3459 | G12: 0.50238889 | H12: 956 | I12: 0.37077778 | J12: 0.7835 | K12: 9624 | L12: 843 | M12: 2781 | N12: 2515 | O12: 522 | P12: 212 | Q12: 1239 | R12: 2.0483333 | S12: 1553
A13: The Guns | B13: 125 | C13: 2 | D13: 107 | E13: 0.53846154 | F13: 3156 | G13: 0.4675 | H13: 1111 | I13: 0.3675 | J13: 0.85111111 | K13: 8911 | L13: 479 | M13: 2101 | N13: 1861 | O13: 600 | P13: 302 | Q13: 963 | R13: 2.0172222 | S13: 1550
A14: Pachiana NinjaBees | B14: 120 | C14: 3 | D14: 111 | E14: 0.51923077 | F14: 2957 | G14: 0.47205556 | H14: 920 | I14: 0.37616667 | J14: 0.80255556 | K14: 8030 | L14: 800 | M14: 2294 | N14: 2059 | O14: 584 | P14: 451 | Q14: 1072 | R14: 1.9661111 | S14: 1534
A15: Guruuu 🐐🐐🐐 | B15: 119 | C15: 2 | D15: 113 | E15: 0.51282051 | F15: 3452 | G15: 0.46122222 | H15: 1136 | I15: 0.35877778 | J15: 0.77994444 | K15: 9805 | L15: 728 | M15: 2197 | N15: 2062 | O15: 592 | P15: 258 | Q15: 1076 | R15: 1.9472222 | S15: 1547
A16: Xanthi Ducks 🦆 | B16: 116 | C16: 3 | D16: 115 | E16: 0.50213675 | F16: 2440 | G16: 0.47727778 | H16: 909 | I16: 0.37833333 | J16: 0.80266667 | K16: 6668 | L16: 619 | M16: 1886 | N16: 1558 | O16: 545 | P16: 298 | Q16: 685 | R16: 2.3705556 | S16: 1547
... A24: Heraklion Snakes | B24: 56 | C24: 2 | D24: 176 | E24: 0.24358974 | F24: 1789 | G24: 0.45133333 | H24: 569 | I24: 0.35161111 | J24: 0.78744444 | K24: 4976 | L24: 490 | M24: 1470 | N24: 1034 | O24: 341 | P24: 179 | Q24: 657 | R24: 1.6505556 | S24: 1550

Sheet Total
A4: Row Labels | B4: Last Year | C4: Games | D4: Games Won | E4: % of Games Won | F4: Wins | G4: Ties | H4: Losses | I4: Win% | J4: FGM | K4: FG% | L4: 3PM | M4: 3P% | N4: FT% | O4: PTS | P4: OREB | Q4: DREB | R4: AST | S4: STL | T4: BLK | U4: TO | V4: A/TO
A5: Karafli SaiTa | B5: 2026 | C5: 179 | D5: 133 | E5: 0.74301676 | F5: 1433 | G5: 47 | H5: 847 | I5: 0.62591319 | J5: 34460 | K5: 0.4756632 | L5: 9077 | M5: 0.36103443 | N5: 0.7971228 | O5: 93486 | P5: 7181 | Q5: 24585 | R5: 20677 | S5: 5622 | T5: 4138 | U5: 10722 | V5: 1.9546507
A6: The Bridgeburners | B6: 2026 | C6: 184 | D6: 122 | E6: 0.66304348 | F6: 1400 | G6: 42 | H6: 950 | I6: 0.59406355 | J6: 30399 | K6: 0.47413494 | L6: 9082 | M6: 0.36852395 | N6: 0.78747992 | O6: 83937 | P6: 7515 | Q6: 25208 | R6: 20863 | S6: 5869 | T6: 3955 | U6: 10628 | V6: 1.9965124
A7: Samarina Dudenbros | B7: 2026 | C7: 179 | D7: 110 | E7: 0.61452514 | F7: 1268 | G7: 33 | H7: 1026 | I7: 0.55199828 | J7: 31570 | K7: 0.47060472 | L7: 9075 | M7: 0.36657649 | N7: 0.8106191 | O7: 87544 | P7: 6515 | Q7: 22479 | R7: 18701 | S7: 5334 | T7: 3020 | U7: 9810 | V7: 1.9047017
A8: Pachiana NinjaBees | B8: 2026 | C8: 179 | D8: 93 | E8: 0.51955307 | F8: 1231 | G8: 41 | H8: 1055 | I8: 0.53781693 | J8: 29050 | K8: 0.46863748 | L8: 8182 | M8: 0.35766654 | N8: 0.79945333 | O8: 78904 | P8: 7001 | Q8: 23173 | R8: 17617 | S8: 5295 | T8: 3845 | U8: 9453 | V8: 1.9043177
A9: purple fuzzy apache pirates | B9: 2026 | C9: 173 | D9: 100 | E9: 0.57803468 | F9: 1198 | G9: 38 | H9: 1013 | I9: 0.54112939 | J9: 32314 | K9: 0.47944869 | L9: 8571 | M9: 0.36337792 | N9: 0.7734201 | O9: 87350 | P9: 7255 | Q9: 26053 | R9: 19694 | S9: 4956 | T9: 3101 | U9: 10783 | V9: 1.8278469
A10: Xanthi Ducks 🦆 | B10: 2026 | C10: 174 | D10: 94 | E10: 0.54022989 | F10: 1185 | G10: 40 | H10: 1037 | I10: 0.53271441 | J10: 27303 | K10: 0.47105714 | L10: 8245 | M10: 0.36692506 | N10: 0.79339639 | O10: 73912 | P10: 6467 | Q10: 22120 | R10: 16829 | S10: 5154 | T10: 3345 | U10: 8110 | V10: 2.1175179
A11: Steven Adams' Moustache | B11: 2026 | C11: 175 | D11: 91 | E11: 0.52 | F11: 1170 | G11: 21 | H11: 1084 | I11: 0.5189011 | J11: 30148 | K11: 0.46728546 | L11: 8535 | M11: 0.36592617 | N11: 0.77118503 | O11: 81556 | P11: 7140 | Q11: 24148 | R11: 18840 | S11: 5058 | T11: 3299 | U11: 9967 | V11: 1.9201761
A12: The Guns | B12: 2026 | C12: 174 | D12: 95 | E12: 0.54597701 | F12: 1154 | G12: 31 | H12: 1077 | I12: 0.51702034 | J12: 29552 | K12: 0.47676606 | L12: 8063 | M12: 0.35686696 | N12: 0.79187621 | O12: 80897 | P12: 6250 | Q12: 22216 | R12: 17901 | S12: 5319 | T12: 3476 | U12: 9678 | V12: 1.8805968
A13: Kourayo Vallecano | B13: 2026 | C13: 172 | D13: 85 | E13: 0.49418605 | F13: 1115 | G13: 31 | H13: 1090 | I13: 0.50559034 | J13: 26241 | K13: 0.46793008 | L13: 7853 | M13: 0.35708894 | N13: 0.77269233 | O13: 71662 | P13: 6331 | Q13: 23520 | R13: 18053 | S13: 4680 | T13: 2941 | U13: 9140 | V13: 2.0015045
A14: Fighting Thaddeus | B14: 2026 | C14: 171 | D14: 79 | E14: 0.4619883 | F14: 1088 | G14: 31 | H14: 1104 | I14: 0.49640126 | J14: 26088 | K14: 0.4675905 | L14: 8034 | M14: 0.36491322 | N14: 0.80086979 | O14: 72134 | P14: 6452 | Q14: 20559 | R14: 15893 | S14: 4597 | T14: 2880 | U14: 8397 | V14: 1.9491368
A15: st.Helens Eruptions | B15: 2026 | C15: 169 | D15: 79 | E15: 0.46745562 | F15: 1034 | G15: 34 | H15: 1129 | I15: 0.47837961 | J15: 27165 | K15: 0.47855345 | L15: 6924 | M15: 0.36170557 | N15: 0.77465662 | O15: 73221 | P15: 6322 | Q15: 19380 | R15: 16367 | S15: 4634 | T15: 2764 | U15: 9182 | V15: 1.8176237
A16: Salonika Devils | B16: 2026 | C16: 171 | D16: 80 | E16: 0.46783626 | F16: 1029 | G16: 41 | H16: 1153 | I16: 0.47210976 | J16: 28267 | K16: 0.46849671 | L16: 7792 | M16: 0.35969373 | N16: 0.78508003 | O16: 76542 | P16: 5789 | Q16: 20043 | R16: 16281 | S16: 4421 | T16: 2520 | U16: 8723 | V16: 1.8970344
... A34: The Others | B34: 2020 | C34: 19 | D34: 4 | E34: 0.21052632 | F34: 86 | G34: 2 | H34: 159 | I34: 0.35222672 | J34: 2446 | K34: 0.43787278 | L34: 844 | M34: 0.35862362 | N34: 0.73284189 | O34: 6543 | P34: 554 | Q34: 1847 | R34: 1360 | S34: 426 | T34: 326 | U34: 788 | V34: 1.7868025
A35: (blank) | E35: #DIV/0! | I35: #DIV/0!

Sheet VsHistory
A4: Row Labels | B4: Match Count | C4: Games Won | D4: % of Games Won | E4: Wins | F4: Ties | G4: Losses | H4: Win%
A5: purple fuzzy apache pirates | B5: 173 | C5: 100 | D5: 0.57803468 | E5: 1198 | F5: 38 | G5: 1013 | H5: 0.54112939
A6: vs The Guns | B6: 11 | C6: 7 | D6: 0.63636364 | E6: 81 | F6: 2 | G6: 60 | H6: 0.57342657
A7: vs Salonika Devils | B7: 11 | C7: 7 | D7: 0.63636364 | E7: 80 | F7: 3 | G7: 60 | H7: 0.56993007
A8: vs Fighting Thaddeus | B8: 10 | C8: 7 | D8: 0.7 | E8: 82 | F8: 0 | G8: 48 | H8: 0.63076923
A9: vs Steven Adams' Moustache | B9: 10 | C9: 6 | D9: 0.6 | E9: 70 | F9: 1 | G9: 59 | H9: 0.54230769
A10: vs st.Helens Eruptions | B10: 10 | C10: 2 | D10: 0.2 | E10: 51 | F10: 4 | G10: 75 | H10: 0.40769231
A11: vs Guruuu 🐐🐐🐐 | B11: 9 | C11: 4 | D11: 0.44444444 | E11: 61 | F11: 2 | G11: 54 | H11: 0.52991453
A12: vs Karafli SaiTa | B12: 9 | C12: 4 | D12: 0.44444444 | E12: 51 | F12: 2 | G12: 64 | H12: 0.44444444
A13: vs Pachiana NinjaBees | B13: 9 | C13: 5 | D13: 0.55555556 | E13: 57 | F13: 1 | G13: 59 | H13: 0.49145299
A14: vs The Bridgeburners | B14: 9 | C14: 7 | D14: 0.77777778 | E14: 74 | F14: 2 | G14: 41 | H14: 0.64102564
A15: vs Tsarlatans | B15: 8 | C15: 3 | D15: 0.375 | E15: 44 | F15: 3 | G15: 57 | H15: 0.4375
A16: vs Xanthi Ducks 🦆 | B16: 8 | C16: 4 | D16: 0.5 | E16: 49 | F16: 1 | G16: 54 | H16: 0.47596154
... A34: vs The Others | B34: 1 | C34: 1 | D34: 1 | E34: 9 | F34: 0 | G34: 4 | H34: 0.69230769

Sheet VsHistoryMatrix
B4: Column Labels
B5: Fighting Thaddeus | D5: Guruuu 🐐🐐🐐 | F5: Heraklion Snakes | H5: Hércules Pals | J5: Karafli SaiTa | L5: Knights of Ni | N5: Kourayo Vallecano | P5: LRBP PR3DATORS | R5: Pachiana NinjaBees | T5: Paralouistas | V5: purple fuzzy apache pirates | X5: Salonika Devils | Z5: Samarina Dudenbros | AB5: st.Helens Eruptions | AD5: Steven Adams' Moustache | AF5: The Bad Boys | AH5: The Bridgeburners | AJ5: The Guns | AL5: Tsarlatans | AN5: Xanthi Ducks 🦆
A6: Row Labels | B6: Match Count | C6: W % | D6: Match Count | E6: W % | F6: Match Count | G6: W % | H6: Match Count | I6: W % | J6: Match Count | K6: W % | L6: Match Count | M6: W % | N6: Match Count | O6: W % | P6: Match Count | Q6: W % | R6: Match Count | S6: W % | T6: Match Count | U6: W % | V6: Match Count | W6: W % | X6: Match Count | Y6: W % | Z6: Match Count | AA6: W % | AB6: Match Count | AC6: W % | AD6: Match Count | AE6: W % | AF6: Match Count | AG6: W % | AH6: Match Count | AI6: W % | AJ6: Match Count | AK6: W % | AL6: Match Count | AM6: W % | AN6: Match Count | AO6: W %
A7: vs The Others | B7: 1 | C7: 1 | D7: 1 | E7: 0 | J7: 1 | K7: 1 | N7: 1 | O7: 1 | R7: 1 | S7: 1 | V7: 1 | W7: 1 | X7: 1 | Y7: 0 | Z7: 1 | AA7: 1 | AB7: 1 | AC7: 1 | AD7: 1 | AE7: 1 | AH7: 1 | AI7: 1 | AJ7: 1 | AK7: 0 | AL7: 1 | AM7: 1 | AN7: 1 | AO7: 1
A8: vs Baltimore Hercules | B8: 4 | C8: 0.75 | D8: 5 | E8: 0.8 | F8: 2 | G8: 1 | J8: 4 | K8: 0.5 | L8: 5 | M8: 0.4 | N8: 6 | O8: 0.5 | P8: 3 | Q8: 1 | R8: 6 | S8: 0.33333333 | T8: 2 | U8: 0.5 | V8: 3 | W8: 0.66666667 | X8: 4 | Y8: 0.75 | Z8: 6 | AA8: 0.66666667 | AB8: 4 | AC8: 0.5 | AD8: 6 | AE8: 0.66666667 | AF8: 5 | AG8: 0.6 | AH8: 5 | AI8: 1 | AJ8: 7 | AK8: 0.85714286 | AL8: 3 | AM8: 0.66666667 | AN8: 6 | AO8: 0.66666667
A9: vs Donkey Rolls | B9: 6 | C9: 0.33333333 | D9: 5 | E9: 0.8 | J9: 6 | K9: 1 | L9: 2 | M9: 0.5 | N9: 5 | O9: 0.4 | P9: 2 | Q9: 1 | R9: 5 | S9: 0.8 | V9: 7 | W9: 0.57142857 | X9: 7 | Y9: 0.57142857 | Z9: 4 | AA9: 1 | AB9: 7 | AC9: 0.57142857 | AD9: 5 | AE9: 0.8 | AF9: 1 | AG9: 0 | AH9: 8 | AI9: 0.75 | AJ9: 5 | AK9: 0.6 | AL9: 5 | AM9: 0.8 | AN9: 4 | AO9: 0.5
A10: vs Drogalo Mountain Goats | B10: 3 | C10: 0.33333333 | D10: 1 | E10: 0 | J10: 4 | K10: 0.75 | N10: 3 | O10: 0.33333333 | R10: 3 | S10: 0.66666667 | V10: 3 | W10: 0 | X10: 3 | Y10: 0.66666667 | Z10: 3 | AA10: 0.66666667 | AB10: 4 | AC10: 0.25 | AD10: 3 | AE10: 0.33333333 | AH10: 4 | AI10: 0.5 | AJ10: 3 | AK10: 0.33333333 | AL10: 1 | AM10: 0 | AN10: 3 | AO10: 0
A11: vs Fighting Thaddeus | D11: 8 | E11: 0.375 | F11: 3 | G11: 0.33333333 | H11: 1 | I11: 0 | J11: 12 | K11: 0.75 | L11: 4 | M11: 0.25 | N11: 8 | O11: 0.375 | P11: 5 | Q11: 0.6 | R11: 9 | S11: 0.44444444 | T11: 3 | U11: 0.33333333 | V11: 10 | W11: 0.7 | X11: 10 | Y11: 0.4 | Z11: 9 | AA11: 0.66666667 | AB11: 10 | AC11: 0.7 | AD11: 7 | AE11: 0.28571429 | AF11: 4 | AG11: 0 | AH11: 10 | AI11: 0.5 | AJ11: 8 | AK11: 0.625 | AL11: 7 | AM11: 0.71428571 | AN11: 9 | AO11: 0.44444444
A12: vs Guruuu 🐐🐐🐐 | B12: 8 | C12: 0.625 | F12: 3 | G12: 0 | H12: 1 | I12: 0 | J12: 9 | K12: 0.66666667 | L12: 5 | M12: 0.2 | N12: 6 | O12: 0.5 | P12: 4 | Q12: 1 | R12: 5 | S12: 0.6 | T12: 3 | U12: 0.33333333 | V12: 9 | W12: 0.44444444 | X12: 7 | Y12: 0.28571429 | Z12: 6 | AA12: 0.66666667 | AB12: 7 | AC12: 0.85714286 | AD12: 6 | AE12: 0.5 | AF12: 4 | AG12: 0.25 | AH12: 9 | AI12: 0.77777778 | AJ12: 6 | AK12: 0.83333333 | AL12: 9 | AM12: 0.66666667 | AN12: 7 | AO12: 0.57142857
A13: vs Heraklion Snakes | B13: 3 | C13: 0.66666667 | D13: 3 | E13: 1 | H13: 1 | I13: 1 | J13: 3 | K13: 1 | L13: 2 | M13: 1 | N13: 3 | O13: 1 | P13: 3 | Q13: 1 | R13: 3 | S13: 0.66666667 | T13: 3 | U13: 0.33333333 | V13: 3 | W13: 1 | X13: 3 | Y13: 0.66666667 | Z13: 3 | AA13: 1 | AB13: 3 | AC13: 0.66666667 | AD13: 3 | AE13: 1 | AF13: 3 | AG13: 0.33333333 | AH13: 3 | AI13: 1 | AJ13: 3 | AK13: 1 | AL13: 3 | AM13: 0.33333333 | AN13: 3 | AO13: 1
A14: vs Hércules Pals | B14: 1 | C14: 1 | D14: 1 | E14: 1 | F14: 1 | G14: 0 | J14: 1 | K14: 1 | L14: 1 | M14: 1 | N14: 1 | O14: 1 | P14: 1 | Q14: 1 | R14: 1 | S14: 0 | V14: 1 | W14: 1 | X14: 1 | Y14: 0 | Z14: 1 | AA14: 1 | AB14: 1 | AC14: 0 | AD14: 1 | AE14: 0 | AF14: 1 | AG14: 1 | AH14: 1 | AI14: 0 | AJ14: 1 | AK14: 1 | AL14: 1 | AM14: 1 | AN14: 1 | AO14: 0
A15: vs Karafli SaiTa | B15: 12 | C15: 0.16666667 | D15: 9 | E15: 0.33333333 | F15: 3 | G15: 0 | H15: 1 | I15: 0 | L15: 4 | M15: 0 | N15: 10 | O15: 0.6 | P15: 4 | Q15: 0 | R15: 8 | S15: 0.125 | T15: 3 | U15: 0 | V15: 9 | W15: 0.44444444 | X15: 10 | Y15: 0.2 | Z15: 11 | AA15: 0.45454545 | AB15: 11 | AC15: 0.090909091 | AD15: 8 | AE15: 0.375 | AF15: 4 | AG15: 0 | AH15: 11 | AI15: 0.18181818 | AJ15: 9 | AK15: 0.22222222 | AL15: 7 | AM15: 0 | AN15: 9 | AO15: 0.22222222
A16: vs Knights of Ni | B16: 4 | C16: 0.75 | D16: 5 | E16: 0.8 | F16: 2 | G16: 0 | H16: 1 | I16: 0 | J16: 4 | K16: 1 | N16: 7 | O16: 0.85714286 | P16: 4 | Q16: 1 | R16: 7 | S16: 0.71428571 | T16: 3 | U16: 1 | V16: 5 | W16: 1 | X16: 6 | Y16: 0.83333333 | Z16: 6 | AA16: 1 | AB16: 5 | AC16: 0.4 | AD16: 7 | AE16: 0.71428571 | AF16: 6 | AG16: 0.16666667 | AH16: 5 | AI16: 0.6 | AJ16: 7 | AK16: 0.71428571 | AL16: 5 | AM16: 0.6 | AN16: 6 | AO16: 0.33333333
A17: vs Kourayo Vallecano | B17: 8 | C17: 0.625 | D17: 6 | E17: 0.5 | F17: 3 | G17: 0 | H17: 1 | I17: 0 | J17: 10 | K17: 0.4 | L17: 7 | M17: 0.14285714 | P17: 5 | Q17: 1 | R17: 11 | S17: 0.72727273 | T17: 3 | U17: 0.33333333 | V17: 7 | W17: 0.71428571 | X17: 7 | Y17: 0.71428571 | Z17: 10 | AA17: 0.6 | AB17: 7 | AC17: 0.14285714 | AD17: 12 | AE17: 0.66666667 | AF17: 5 | AG17: 0 | AH17: 8 | AI17: 0.875 | AJ17: 10 | AK17: 0.6 | AL17: 7 | AM17: 0.28571429 | AN17: 10 | AO17: 0.4
A18: vs LRBP PR3DATORS | B18: 5 | C18: 0.4 | D18: 4 | E18: 0 | F18: 3 | G18: 0 | H18: 1 | I18: 0 | J18: 4 | K18: 1 | L18: 4 | M18: 0 | N18: 5 | O18: 0 | R18: 5 | S18: 0.6 | T18: 3 | U18: 0 | V18: 4 | W18: 0.25 | X18: 4 | Y18: 0 | Z18: 5 | AA18: 0.8 | AB18: 4 | AC18: 0 | AD18: 4 | AE18: 0.25 | AF18: 4 | AG18: 0 | AH18: 5 | AI18: 0.6 | AJ18: 5 | AK18: 0.4 | AL18: 4 | AM18: 0.25 | AN18: 4 | AO18: 0.75
A19: vs Pachiana NinjaBees | B19: 9 | C19: 0.44444444 | D19: 5 | E19: 0.4 | F19: 3 | G19: 0.33333333 | H19: 1 | I19: 1 | J19: 8 | K19: 0.875 | L19: 7 | M19: 0.14285714 | N19: 11 | O19: 0.27272727 | P19: 5 | Q19: 0.4 | T19: 3 | U19: 0.33333333 | V19: 9 | W19: 0.55555556 | X19: 9 | Y19: 0.22222222 | Z19: 11 | AA19: 0.63636364 | AB19: 9 | AC19: 0.33333333 | AD19: 10 | AE19: 0.6 | AF19: 7 | AG19: 0.28571429 | AH19: 10 | AI19: 0.6 | AJ19: 10 | AK19: 0.4 | AL19: 6 | AM19: 0.66666667 | AN19: 10 | AO19: 0.6
A20: vs Paralouistas | B20: 3 | C20: 0.66666667 | D20: 3 | E20: 0.66666667 | F20: 3 | G20: 0.33333333 | J20: 3 | K20: 1 | L20: 3 | M20: 0 | N20: 3 | O20: 0.66666667 | P20: 3 | Q20: 1 | R20: 3 | S20: 0.66666667 | V20: 3 | W20: 1 | X20: 3 | Y20: 0.33333333 | Z20: 3 | AA20: 1 | AB20: 3 | AC20: 0.66666667 | AD20: 3 | AE20: 0.66666667 | AF20: 3 | AG20: 0 | AH20: 3 | AI20: 0.33333333 | AJ20: 3 | AK20: 0.66666667 | AL20: 3 | AM20: 0.66666667 | AN20: 3 | AO20: 1
A21: vs purple fuzzy apache pirates | B21: 10 | C21: 0.3 | D21: 9 | E21: 0.44444444 | F21: 3 | G21: 0 | H21: 1 | I21: 0 | J21: 9 | K21: 0.44444444 | L21: 5 | M21: 0 | N21: 7 | O21: 0.28571429 | P21: 4 | Q21: 0.75 | R21: 9 | S21: 0.44444444 | T21: 3 | U21: 0 | X21: 11 | Y21: 0.36363636 | Z21: 7 | AA21: 0.57142857 | AB21: 10 | AC21: 0.8 | AD21: 10 | AE21: 0.4 | AF21: 4 | AG21: 0 | AH21: 9 | AI21: 0.22222222 | AJ21: 11 | AK21: 0.36363636 | AL21: 8 | AM21: 0.625 | AN21: 8 | AO21: 0.5
A22: vs Retsiniakos 21 | B22: 3 | C22: 1 | D22: 1 | E22: 1 | J22: 3 | K22: 0.66666667 | N22: 3 | O22: 0.33333333 | R22: 3 | S22: 1 | V22: 3 | W22: 0.66666667 | X22: 3 | Y22: 0.33333333 | Z22: 3 | AA22: 0.33333333 | AB22: 3 | AC22: 0.66666667 | AD22: 3 | AE22: 0.33333333 | AH22: 3 | AI22: 1 | AJ22: 3 | AK22: 0.66666667 | AL22: 1 | AM22: 1 | AN22: 3 | AO22: 0.33333333
A23: vs Salonika Devils | B23: 10 | C23: 0.5 | D23: 7 | E23: 0.71428571 | F23: 3 | G23: 0.33333333 | H23: 1 | I23: 1 | J23: 10 | K23: 0.7 | L23: 6 | M23: 0.16666667 | N23: 7 | O23: 0.28571429 | P23: 4 | Q23: 1 | R23: 9 | S23: 0.77777778 | T23: 3 | U23: 0.33333333 | V23: 11 | W23: 0.63636364 | Z23: 9 | AA23: 0.33333333 | AB23: 10 | AC23: 0.4 | AD23: 8 | AE23: 0.625 | AF23: 4 | AG23: 0.25 | AH23: 12 | AI23: 0.83333333 | AJ23: 6 | AK23: 0.5 | AL23: 8 | AM23: 0.625 | AN23: 8 | AO23: 0.5
A24: vs Samarina Dudenbros | B24: 9 | C24: 0.33333333 | D24: 6 | E24: 0.16666667 | F24: 3 | G24: 0 | H24: 1 | I24: 0 | J24: 11 | K24: 0.45454545 | L24: 6 | M24: 0 | N24: 10 | O24: 0.4 | P24: 5 | Q24: 0.2 | R24: 11 | S24: 0.27272727 | T24: 3 | U24: 0 | V24: 7 | W24: 0.42857143 | X24: 9 | Y24: 0.66666667 | AB24: 9 | AC24: 0.33333333 | AD24: 11 | AE24: 0.45454545 | AF24: 6 | AG24: 0.16666667 | AH24: 10 | AI24: 0.6 | AJ24: 12 | AK24: 0.33333333 | AL24: 5 | AM24: 0 | AN24: 11 | AO24: 0.72727273
A25: vs st.Helens Eruptions | B25: 10 | C25: 0.3 | D25: 7 | E25: 0.14285714 | F25: 3 | G25: 0.33333333 | H25: 1 | I25: 1 | J25: 11 | K25: 0.90909091 | L25: 5 | M25: 0.6 | N25: 7 | O25: 0.85714286 | P25: 4 | Q25: 1 | R25: 9 | S25: 0.55555556 | T25: 3 | U25: 0.33333333 | V25: 10 | W25: 0.2 | X25: 10 | Y25: 0.6 | Z25: 9 | AA25: 0.66666667 | AD25: 8 | AE25: 0.375 | AF25: 4 | AG25: 0.25 | AH25: 9 | AI25: 0.44444444 | AJ25: 7 | AK25: 0.85714286 | AL25: 8 | AM25: 0.875 | AN25: 8 | AO25: 0.5
A26: vs Steven Adams' Moustache | B26: 7 | C26: 0.71428571 | D26: 6 | E26: 0.5 | F26: 3 | G26: 0 | H26: 1 | I26: 1 | J26: 8 | K26: 0.625 | L26: 7 | M26: 0.28571429 | N26: 12 | O26: 0.33333333 | P26: 4 | Q26: 0.75 | R26: 10 | S26: 0.4 | T26: 3 | U26: 0.33333333 | V26: 10 | W26: 0.6 | X26: 8 | Y26: 0.375 | Z26: 11 | AA26: 0.54545455 | AB26: 8 | AC26: 0.625 | AF26: 6 | AG26: 0.5 | AH26: 9 | AI26: 0.55555556 | AJ26: 9 | AK26: 0.55555556 | AL26: 6 | AM26: 0.5 | AN26: 11 | AO26: 0.54545455
A27: vs The Bad Boys | B27: 4 | C27: 1 | D27: 4 | E27: 0.75 | F27: 3 | G27: 0.66666667 | H27: 1 | I27: 0 | J27: 4 | K27: 1 | L27: 6 | M27: 0.83333333 | N27: 5 | O27: 1 | P27: 4 | Q27: 1 | R27: 7 | S27: 0.71428571 | T27: 3 | U27: 0.66666667 | V27: 4 | W27: 1 | X27: 4 | Y27: 0.75 | Z27: 6 | AA27: 0.83333333 | AB27: 4 | AC27: 0.75 | AD27: 6 | AE27: 0.5 | AH27: 4 | AI27: 1 | AJ27: 6 | AK27: 0.83333333 | AL27: 4 | AM27: 0.5 | AN27: 6 | AO27: 0.66666667
A28: vs The Bridgeburners | B28: 10 | C28: 0.5 | D28: 9 | E28: 0.22222222 | F28: 3 | G28: 0 | H28: 1 | I28: 1 | J28: 11 | K28: 0.72727273 | L28: 5 | M28: 0.2 | N28: 8 | O28: 0.125 | P28: 5 | Q28: 0.4 | R28: 10 | S28: 0.2 | T28: 3 | U28: 0.66666667 | V28: 9 | W28: 0.77777778 | X28: 12 | Y28: 0.16666667 | Z28: 10 | AA28: 0.4 | AB28: 9 | AC28: 0.44444444 | AD28: 9 | AE28: 0.33333333 | AF28: 4 | AG28: 0 | AJ28: 8 | AK28: 0 | AL28: 10 | AM28: 0.3 | AN28: 10 | AO28: 0.3
A29: vs The Guns | B29: 8 | C29: 0.25 | D29: 6 | E29: 0.16666667 | F29: 3 | G29: 0 | H29: 1 | I29: 0 | J29: 9 | K29: 0.77777778 | L29: 7 | M29: 0.28571429 | N29: 10 | O29: 0.4 | P29: 5 | Q29: 0.6 | R29: 10 | S29: 0.6 | T29: 3 | U29: 0.33333333 | V29: 11 | W29: 0.63636364 | X29: 6 | Y29: 0.5 | Z29: 12 | AA29: 0.66666667 | AB29: 7 | AC29: 0.14285714 | AD29: 9 | AE29: 0.44444444 | AF29: 6 | AG29: 0.16666667 | AH29: 8 | AI29: 0.875 | AL29: 6 | AM29: 0.33333333 | AN29: 11 | AO29: 0.54545455
A30: vs The Others | B30: 3 | C30: 0.33333333 | J30: 3 | K30: 1 | L30: 1 | M30: 1 | N30: 2 | O30: 0.5 | R30: 3 | S30: 0.66666667 | V30: 3 | W30: 0.33333333 | X30: 3 | Y30: 0.66666667 | Z30: 3 | AA30: 1 | AB30: 3 | AC30: 0.66666667 | AD30: 3 | AE30: 0.33333333 | AH30: 2 | AI30: 1 | AJ30: 2 | AK30: 0.5 | AL30: 1 | AM30: 1 | AN30: 3 | AO30: 0.66666667
A31: vs The Rookies | B31: 7 | C31: 0.28571429 | D31: 5 | E31: 0.4 | J31: 7 | K31: 1 | L31: 2 | M31: 0.5 | N31: 5 | O31: 0.8 | P31: 1 | Q31: 1 | R31: 4 | S31: 1 | V31: 7 | W31: 0.85714286 | X31: 6 | Y31: 1 | Z31: 5 | AA31: 0.6 | AB31: 6 | AC31: 0.83333333 | AD31: 4 | AE31: 0.75 | AF31: 1 | AG31: 0 | AH31: 7 | AI31: 0.85714286 | AJ31: 5 | AK31: 0.6 | AL31: 5 | AM31: 0.8 | AN31: 5 | AO31: 0.8
A32: vs The walkinng dead | B32: 2 | C32: 0.5 | J32: 2 | K32: 1 | N32: 2 | O32: 0.5 | R32: 2 | S32: 0.5 | V32: 2 | W32: 0 | X32: 2 | Y32: 1 | Z32: 2 | AA32: 0 | AB32: 2 | AC32: 1 | AD32: 2 | AE32: 0.5 | AH32: 2 | AI32: 1 | AJ32: 2 | AK32: 0.5 | AN32: 2 | AO32: 0.5
A33: vs Tsarlatans | B33: 7 | C33: 0.28571429 | D33: 9 | E33: 0.33333333 | F33: 3 | G33: 0.33333333 | H33: 1 | I33: 0 | J33: 7 | K33: 0.85714286 | L33: 5 | M33: 0.4 | N33: 7 | O33: 0.71428571 | P33: 4 | Q33: 0.75 | R33: 6 | S33: 0.33333333 | T33: 3 | U33: 0.33333333 | V33: 8 | W33: 0.375 | X33: 8 | Y33: 0.375 | Z33: 5 | AA33: 1 | AB33: 8 | AC33: 0.125 | AD33: 6 | AE33: 0.5 | AF33: 4 | AG33: 0.5 | AH33: 10 | AI33: 0.7 | AJ33: 6 | AK33: 0.66666667 | AN33: 5 | AO33: 1
A34: vs Tsoko Marokana | B34: 2 | C34: 0 | J34: 2 | K34: 1 | N34: 2 | O34: 0.5 | R34: 2 | S34: 0.5 | V34: 2 | W34: 0.5 | X34: 2 | Y34: 1 | Z34: 2 | AA34: 0.5 | AB34: 2 | AC34: 0.5 | AD34: 2 | AE34: 1 | AH34: 2 | AI34: 1 | AJ34: 2 | AK34: 1 | AN34: 2 | AO34: 0.5
A35: vs Underdogs | B35: 3 | C35: 0.66666667 | D35: 2 | E35: 0.5 | J35: 4 | K35: 0.5 | L35: 3 | M35: 0 | N35: 6 | O35: 0.66666667 | R35: 7 | S35: 0.42857143 | V35: 4 | W35: 0.5 | X35: 4 | Y35: 0.25 | Z35: 5 | AA35: 0.4 | AB35: 4 | AC35: 0.5 | AD35: 7 | AE35: 0.71428571 | AF35: 2 | AG35: 0 | AH35: 4 | AI35: 1 | AJ35: 6 | AK35: 0.83333333 | AL35: 2 | AM35: 0 | AN35: 5 | AO35: 0.6
A36: vs Xanthi Ducks 🦆 | B36: 9 | C36: 0.55555556 | D36: 7 | E36: 0.42857143 | F36: 3 | G36: 0 | H36: 1 | I36: 1 | J36: 9 | K36: 0.66666667 | L36: 6 | M36: 0.5 | N36: 10 | O36: 0.6 | P36: 4 | Q36: 0.25 | R36: 10 | S36: 0.4 | T36: 3 | U36: 0 | V36: 8 | W36: 0.5 | X36: 8 | Y36: 0.5 | Z36: 11 | AA36: 0.27272727 | AB36: 8 | AC36: 0.5 | AD36: 11 | AE36: 0.45454545 | AF36: 6 | AG36: 0.33333333 | AH36: 10 | AI36: 0.7 | AJ36: 11 | AK36: 0.45454545 | AL36: 5 | AM36: 0

Sheet Records
A1: ALL YEARS
A3: Category | B3: Value | D3: Team | E3: Opponent | G3: Period | I3: All Time Rank | K3: Team | L3: # of records
A4: Wins | B4: =MAX(Data!$H:$H) -> 13 | C4: =COUNTIF(Data!$H:$H,Records!$B4) -> 6 | D4: =INDEX(Data!$E:$E,MATCH(Records!$B4,Data!$H:$H,0)) -> Pachiana NinjaBees | E4: =INDEX(Data!$K:$K,MATCH(Records!$B4,Data!$H:$H,0)) -> vs Underdogs | G4: =INDEX(Data!$C:$C,MATCH(Records!$B4,Data!$H:$H,0)) -> 9 | H4: =INDEX(Data!$A:$A,MATCH(Records!$B4,Data!$H:$H,0)) -> 2019 | K4: Karafli SaiTa | L4: =COUNTIF($D$4:$D$22,K4) -> 3
D5: Samarina Dudenbros | E5: vs Underdogs | G5: 14 | H5: 2019 | K5: Samarina Dudenbros | L5: =COUNTIF($D$4:$D$22,K5) -> 3
D6: The Bridgeburners | E6: vs Samarina Dudenbros | G6: 7 | H6: 2020 | K6: purple fuzzy apache pirates | L6: =COUNTIF($D$4:$D$22,K6) -> 2
D7: Karafli SaiTa | E7: vs Donkey Rolls | G7: 14 | H7: 2023 | K7: Steven Adams' Moustache | L7: =COUNTIF($D$4:$D$22,K7) -> 2
D8: Xanthi Ducks 🦆 | E8: vs st.Helens Eruptions | G8: 7 | H8: 2024 | K8: Pachiana NinjaBees | L8: =COUNTIF($D$4:$D$22,K8) -> 2
D9: Karafli SaiTa | E9: vs The Guns | G9: 3 | H9: 2025 | K9: Xanthi Ducks 🦆 | L9: =COUNTIF($D$4:$D$22,K9) -> 1
A10: FGM | B10: =MAX(Data!$M:$M) -> 333 | C10: =COUNTIF(Data!$M:$M,Records!$B10) -> 1 | D10: =INDEX(Data!$E:$E,MATCH(Records!$B10,Data!$M:$M,0)) -> purple fuzzy apache pirates | E10: =INDEX(Data!$K:$K,MATCH(Records!$B10,Data!$M:$M,0)) -> vs Guruuu 🐐🐐🐐 | G10: =INDEX(Data!$C:$C,MATCH(Records!$B10,Data!$M:$M,0)) -> 17 | H10: =INDEX(Data!$A:$A,MATCH(Records!$B10,Data!$M:$M,0)) -> 2024 | K10: Tsarlatans | L10: =COUNTIF($D$4:$D$22,K10) -> 1
A11: FG% | B11: =MAX(Data!$N:$N) -> 0.608 | C11: =COUNTIF(Data!$N:$N,Records!$B11) -> 1 | D11: =INDEX(Data!$E:$E,MATCH(Records!$B11,Data!$N:$N,0)) -> Tsarlatans | E11: =INDEX(Data!$K:$K,MATCH(Records!$B11,Data!$N:$N,0)) -> vs Fighting Thaddeus | G11: =INDEX(Data!$C:$C,MATCH(Records!$B11,Data!$N:$N,0)) -> 9 | H11: =INDEX(Data!$A:$A,MATCH(Records!$B11,Data!$N:$N,0)) -> 2025 | K11: Underdogs | L11: =COUNTIF($D$4:$D$22,K11) -> 1
A12: 3PM | B12: =MAX(Data!$O:$O) -> 122 | C12: =COUNTIF(Data!$O:$O,Records!$B12) -> 1 | D12: =INDEX(Data!$E:$E,MATCH(Records!$B12,Data!$O:$O,0)) -> Samarina Dudenbros | E12: =INDEX(Data!$K:$K,MATCH(Records!$B12,Data!$O:$O,0)) -> vs The Bad Boys | G12: =INDEX(Data!$C:$C,MATCH(Records!$B12,Data!$O:$O,0)) -> 17 | H12: =INDEX(Data!$A:$A,MATCH(Records!$B12,Data!$O:$O,0)) -> 2025 | K12: Fighting Thaddeus | L12: =COUNTIF($D$4:$D$22,K12) -> 1
A13: 3P% | B13: =MAX(Data!$P:$P) -> 0.537 | C13: =COUNTIF(Data!$P:$P,Records!$B13) -> 1 | D13: =INDEX(Data!$E:$E,MATCH(Records!$B13,Data!$P:$P,0)) -> Underdogs | E13: =INDEX(Data!$K:$K,MATCH(Records!$B13,Data!$P:$P,0)) -> vs Steven Adams' Moustache | G13: =INDEX(Data!$C:$C,MATCH(Records!$B13,Data!$P:$P,0)) -> 19 | H13: =INDEX(Data!$A:$A,MATCH(Records!$B13,Data!$P:$P,0)) -> 2018 | K13: The Bridgeburners | L13: =COUNTIF($D$4:$D$22,K13) -> 1
A14: FT% | B14: =MAX(Data!$Q:$Q) -> 0.956 | C14: =COUNTIF(Data!$Q:$Q,Records!$B14)-1 -> 1 | D14: =INDEX(Data!$E:$E,MATCH(Records!$B14,Data!$Q:$Q,0)) -> Karafli SaiTa | E14: =INDEX(Data!$K:$K,MATCH(Records!$B14,Data!$Q:$Q,0)) -> vs Baltimore Hercules | G14: =INDEX(Data!$C:$C,MATCH(Records!$B14,Data!$Q:$Q,0)) -> 1 | H14: =INDEX(Data!$A:$A,MATCH(Records!$B14,Data!$Q:$Q,0)) -> 2023 | K14: The Bad Boys | L14: =COUNTIF($D$4:$D$22,K14) -> 1
A15: PTS | B15: =MAX(Data!$R:$R) -> 892 | C15: =COUNTIF(Data!$R:$R,Records!$B15) -> 1 | D15: =INDEX(Data!$E:$E,MATCH(Records!$B15,Data!$R:$R,0)) -> purple fuzzy apache pirates | E15: =INDEX(Data!$K:$K,MATCH(Records!$B15,Data!$R:$R,0)) -> vs Guruuu 🐐🐐🐐 | G15: =INDEX(Data!$C:$C,MATCH(Records!$B15,Data!$R:$R,0)) -> 17 | H15: =INDEX(Data!$A:$A,MATCH(Records!$B15,Data!$R:$R,0)) -> 2024 | K15: Kourayo Vallecano | L15: =COUNTIF($D$4:$D$22,K15) -> 1
A16: OREB | B16: =MAX(Data!$S:$S) -> 87 | C16: =COUNTIF(Data!$S:$S,Records!$B16) -> 1 | D16: =INDEX(Data!$E:$E,MATCH(Records!$B16,Data!$S:$S,0)) -> Fighting Thaddeus | E16: =INDEX(Data!$K:$K,MATCH(Records!$B16,Data!$S:$S,0)) -> vs Kourayo Vallecano | G16: =INDEX(Data!$C:$C,MATCH(Records!$B16,Data!$S:$S,0)) -> 15 | H16: =INDEX(Data!$A:$A,MATCH(Records!$B16,Data!$S:$S,0)) -> 2024
A17: DREB | B17: =MAX(Data!$T:$T) -> 245 | C17: =COUNTIF(Data!$T:$T,Records!$B17) -> 1 | D17: =INDEX(Data!$E:$E,MATCH(Records!$B17,Data!$T:$T,0)) -> Steven Adams' Moustache | E17: =INDEX(Data!$K:$K,MATCH(Records!$B17,Data!$T:$T,0)) -> vs Tsarlatans | G17: =INDEX(Data!$C:$C,MATCH(Records!$B17,Data!$T:$T,0)) -> 11 | H17: =INDEX(Data!$A:$A,MATCH(Records!$B17,Data!$T:$T,0)) -> 2021
A18: AST | B18: =MAX(Data!$U:$U) -> 243 | C18: =COUNTIF(Data!$U:$U,Records!$B18) -> 2 | D18: =INDEX(Data!$E:$E,MATCH(Records!$B18,Data!$U:$U,0)) -> Samarina Dudenbros | E18: =INDEX(Data!$K:$K,MATCH(Records!$B18,Data!$U:$U,0)) -> vs The Bridgeburners | G18: =INDEX(Data!$C:$C,MATCH(Records!$B18,Data!$U:$U,0)) -> 16 | H18: =INDEX(Data!$A:$A,MATCH(Records!$B18,Data!$U:$U,0)) -> 2026
A19: STL | B19: =MAX(Data!$V:$V) -> 66 | C19: =COUNTIF(Data!$V:$V,Records!$B19) -> 1 | D19: =INDEX(Data!$E:$E,MATCH(Records!$B19,Data!$V:$V,0)) -> Steven Adams' Moustache | E19: =INDEX(Data!$K:$K,MATCH(Records!$B19,Data!$V:$V,0)) -> vs Kourayo Vallecano | G19: =INDEX(Data!$C:$C,MATCH(Records!$B19,Data!$V:$V,0)) -> 4 | H19: =INDEX(Data!$A:$A,MATCH(Records!$B19,Data!$V:$V,0)) -> 2022
A20: BLK | B20: =MAX(Data!$W:$W) -> 47 | C20: =COUNTIF(Data!$W:$W,Records!$B20) -> 1 | D20: =INDEX(Data!$E:$E,MATCH(Records!$B20,Data!$W:$W,0)) -> Pachiana NinjaBees | E20: =INDEX(Data!$K:$K,MATCH(Records!$B20,Data!$W:$W,0)) -> vs Kourayo Vallecano | G20: =INDEX(Data!$C:$C,MATCH(Records!$B20,Data!$W:$W,0)) -> 17 | H20: =INDEX(Data!$A:$A,MATCH(Records!$B20,Data!$W:$W,0)) -> 2024
A21: TO | B21: =MIN(Data!$X:$X) -> 8 | C21: =COUNTIF(Data!$X:$X,Records!$B21) -> 1 | D21: =INDEX(Data!$E:$E,MATCH(Records!$B21,Data!$X:$X,0)) -> The Bad Boys | E21: =INDEX(Data!$K:$K,MATCH(Records!$B21,Data!$X:$X,0)) -> vs The Guns | G21: =INDEX(Data!$C:$C,MATCH(Records!$B21,Data!$X:$X,0)) -> 7 | H21: =INDEX(Data!$A:$A,MATCH(Records!$B21,Data!$X:$X,0)) -> 2022
A22: A/TO | B22: =MAX(Data!$Y:$Y) -> 4.32 | C22: =COUNTIF(Data!$Y:$Y,Records!$B22) -> 1 | D22: =INDEX(Data!$E:$E,MATCH(Records!$B22,Data!$Y:$Y,0)) -> Kourayo Vallecano | E22: =INDEX(Data!$K:$K,MATCH(Records!$B22,Data!$Y:$Y,0)) -> vs The Rookies | G22: =INDEX(Data!$C:$C,MATCH(Records!$B22,Data!$Y:$Y,0)) -> 14 | H22: =INDEX(Data!$A:$A,MATCH(Records!$B22,Data!$Y:$Y,0)) -> 2019
A24: 2018
A26: Category | B26: Value | D26: Team | E26: Opponent | G26: Period | I26: All Time Rank | K26: Team | L26: # of records
A27: Wins | B27: =_xlfn.MAXIFS(Data!$H:$H,Data!$A:$A,Records!$A$24) -> 12 | C27: =COUNTIFS(Data!$H:$H,Records!$B27,Data!$A:$A,Records!$A$24) -> 8 | D27: {=INDEX(Data!$E:$E,MATCH(1,INDEX((Records!$B27=Data!$H:$H)*($A$24=Data!$A:$A),0,1),0))} -> Pachiana NinjaBees | E27: {=INDEX(Data!$K:$K,MATCH(1,INDEX((Records!$B27=Data!$H:$H)*($A$24=Data!$A:$A),0,1),0))} -> vs purple fuzzy apache pirates | G27: {=INDEX(Data!$C:$C,MATCH(1,INDEX((Records!$B27=Data!$H:$H)*($A$24=Data!$A:$A),0,1),0))} -> 4 | I27: =RANK(B27,Data!$H:$H) -> 7 | K27: {=INDEX(Data!$E:$E,MATCH(1,INDEX((Records!$B27=Data!$H:$H)*($A$24=Data!$A:$A),0,1),0))} -> Pachiana NinjaBees | L27: =COUNTIF($D$27:$D$50,K27) -> 3
D28: Samarina Dudenbros | E28: vs Drogalo Mountain Goats | G28: 7 | I28: =+I27 -> 7 | K28: Salonika Devils | L28: =COUNTIF($D$27:$D$50,K28) -> 3
D29: Xanthi Ducks 🦆 | E29: vs The Guns | G29: 7 | I29: =+I28 -> 7 | K29: Donkey Rolls | L29: =COUNTIF($D$27:$D$50,K29) -> 3
D30: Samarina Dudenbros | E30: vs Underdogs | G30: 14 | I30: =+I29 -> 7 | K30: Samarina Dudenbros | L30: =COUNTIF($D$27:$D$50,K30)-1 -> 2
D31: The Others | E31: vs Underdogs | G31: 16 | I31: =+I30 -> 7 | K31: The Others | L31: =COUNTIF($D$27:$D$50,K31) -> 2
D32: Salonika Devils | E32: vs Underdogs | G32: 17 | I32: =+I31 -> 7 | K32: {=INDEX(Data!$E:$E,MATCH(1,INDEX((Records!$B37=Data!$O:$O)*($A$24=Data!$A:$A),0,1),0))} -> The walkinng dead | L32: =COUNTIF($D$27:$D$50,K32)-1 -> 2
D33: Drogalo Mountain Goats | E33: vs The Guns | G33: 17 | I33: =+I32 -> 7 | K33: {=INDEX(Data!$E:$E,MATCH(1,INDEX((Records!$B41=Data!$P:$P)*($A$24=Data!$A:$A),0,1),0))} -> Underdogs | L33: =COUNTIF($D$27:$D$50,K33) -> 2
D34: Donkey Rolls | E34: vs Underdogs | G34: 18 | I34: =+I33 -> 7 | K34: {=INDEX(Data!$E:$E,MATCH(1,INDEX((Records!$B44=Data!$S:$S)*($A$24=Data!$A:$A),0,1),0))} -> Fighting Thaddeus | L34: =COUNTIF($D$27:$D$50,K34) -> 2
A35: FGM | B35: =_xlfn.MAXIFS(Data!$M:$M,Data!$A:$A,Records!$A$24) -> 261 | C35: =COUNTIFS(Data!$M:$M,Records!$B35,Data!$A:$A,Records!$A$24) -> 1 | D35: {=INDEX(Data!$E:$E,MATCH(1,INDEX((Records!$B35=Data!$M:$M)*($A$24=Data!$A:$A),0,1),0))} -> Karafli SaiTa | E35: {=INDEX(Data!$K:$K,MATCH(1,INDEX((Records!$B35=Data!$M:$M)*($A$24=Data!$A:$A),0,1),0))} -> vs Fighting Thaddeus | G35: {=INDEX(Data!$C:$C,MATCH(1,INDEX((Records!$B35=Data!$M:$M)*($A$24=Data!$A:$A),0,1),0))} -> 18 | I35: =RANK(B35,Data!$M:$M) -> 39 | K35: Xanthi Ducks 🦆 | L35: =COUNTIF($D$27:$D$50,K35) -> 1
A36: FG% | B36: =_xlfn.MAXIFS(Data!$N:$N,Data!$A:$A,Records!$A$24) -> 0.544 | C36: =COUNTIFS(Data!$N:$N,Records!$B36,Data!$A:$A,Records!$A$24) -> 1 | D36: {=INDEX(Data!$E:$E,MATCH(1,INDEX((Records!$B36=Data!$N:$N)*($A$24=Data!$A:$A),0,1),0))} -> Donkey Rolls | E36: {=INDEX(Data!$K:$K,MATCH(1,INDEX((Records!$B36=Data!$N:$N)*($A$24=Data!$A:$A),0,1),0))} -> vs The Bridgeburners | G36: {=INDEX(Data!$C:$C,MATCH(1,INDEX((Records!$B36=Data!$N:$N)*($A$24=Data!$A:$A),0,1),0))} -> 3 | I36: =RANK(B36,Data!$N:$N) -> 45 | K36: Drogalo Mountain Goats | L36: =COUNTIF($D$27:$D$50,K36) -> 1
A37: 3PM | B37: =_xlfn.MAXIFS(Data!$O:$O,Data!$A:$A,Records!$A$24) -> 71 | C37: =COUNTIFS(Data!$O:$O,Records!$B37,Data!$A:$A,Records!$A$24) -> 4 | D37: {=INDEX(Data!$E:$E,MATCH(1,INDEX((Records!$B37=Data!$O:$O)*($A$24=Data!$A:$A),0,1),0))} -> The walkinng dead | E37: {=INDEX(Data!$K:$K,MATCH(1,INDEX((Records!$B37=Data!$O:$O)*($A$24=Data!$A:$A),0,1),0))} -> vs Xanthi Ducks 🦆 | G37: {=INDEX(Data!$C:$C,MATCH(1,INDEX((Records!$B37=Data!$O:$O)*($A$24=Data!$A:$A),0,1),0))} -> 9 | I37: =RANK(B37,Data!$O:$O) -> 144 | K37: {=INDEX(Data!$E:$E,MATCH(1,INDEX((Records!$B35=Data!$M:$M)*($A$24=Data!$A:$A),0,1),0))} -> Karafli SaiTa | L37: =COUNTIF($D$27:$D$50,K37) -> 1
D38: Samarina Dudenbros | E38: vs Fighting Thaddeus | G38: 10 | I38: =+I37 -> 144
D39: The walkinng dead | E39: vs Steven Adams' Moustache | G39: 11 | I39: =+I38 -> 144
D40: Pachiana NinjaBees | E40: vs st.Helens Eruptions | G40: 3rd place | I40: =+I39 -> 144
A41: 3P% | B41: =_xlfn.MAXIFS(Data!$P:$P,Data!$A:$A,Records!$A$24) -> 0.537 | C41: =COUNTIFS(Data!$P:$P,Records!$B41,Data!$A:$A,Records!$A$24) -> 1 | D41: {=INDEX(Data!$E:$E,MATCH(1,INDEX((Records!$B41=Data!$P:$P)*($A$24=Data!$A:$A),0,1),0))} -> Underdogs | E41: {=INDEX(Data!$K:$K,MATCH(1,INDEX((Records!$B41=Data!$P:$P)*($A$24=Data!$A:$A),0,1),0))} -> vs Steven Adams' Moustache | G41: {=INDEX(Data!$C:$C,MATCH(1,INDEX((Records!$B41=Data!$P:$P)*($A$24=Data!$A:$A),0,1),0))} -> 19 | I41: =RANK(B41,Data!$P:$P) -> 1
A42: FT% | B42: =_xlfn.MAXIFS(Data!$Q:$Q,Data!$A:$A,Records!$A$24) -> 0.907 | C42: =COUNTIFS(Data!$Q:$Q,Records!$B42,Data!$A:$A,Records!$A$24) -> 1 | D42: {=INDEX(Data!$E:$E,MATCH(1,INDEX((Records!$B42=Data!$Q:$Q)*($A$24=Data!$A:$A),0,1),0))} -> Donkey Rolls | E42: {=INDEX(Data!$K:$K,MATCH(1,INDEX((Records!$B42=Data!$Q:$Q)*($A$24=Data!$A:$A),0,1),0))} -> vs Retsiniakos 21 | G42: {=INDEX(Data!$C:$C,MATCH(1,INDEX((Records!$B42=Data!$Q:$Q)*($A$24=Data!$A:$A),0,1),0))} -> 1 | I42: =RANK(B42,Data!$Q:$Q) -> 26
A43: PTS | B43: =_xlfn.MAXIFS(Data!$R:$R,Data!$A:$A,Records!$A$24) -> 692 | C43: =COUNTIFS(Data!$R:$R,Records!$B43,Data!$A:$A,Records!$A$24) -> 1 | D43: {=INDEX(Data!$E:$E,MATCH(1,INDEX((Records!$B43=Data!$R:$R)*($A$24=Data!$A:$A),0,1),0))} -> Salonika Devils | E43: {=INDEX(Data!$K:$K,MATCH(1,INDEX((Records!$B43=Data!$R:$R)*($A$24=Data!$A:$A),0,1),0))} -> vs Drogalo Mountain Goats | G43: {=INDEX(Data!$C:$C,MATCH(1,INDEX((Records!$B43=Data!$R:$R)*($A$24=Data!$A:$A),0,1),0))} -> 8 | I43: =RANK(B43,Data!$R:$R) -> 54
...

Sheet Data
A1: Year | B1: Regular/ Playoffs | C1: Period | D1: Match No | E1: Team | F1: Manager | G1: Games Won | H1: W | I1: L | J1: D | K1: vs Opponent | L1: vs Manager | M1: FGM | N1: FG% | O1: 3PM | P1: 3P% | Q1: FT% | R1: PTS | S1: OREB | T1: DREB | U1: AST | V1: STL | W1: BLK | X1: TO | Y1: A/TO
A2: 2018 | B2: Regular | C2: 1 | D2: 1 | E2: The Others | F2: Miggianis | G2: =IF(H2+0.5*J2>6.5,1,0) -> 0 | H2: 5 | I2: 7 | J2: 1 | K2: vs The Bridgeburners | L2: vs Fanis | M2: 118 | N2: 0.411 | O2: 37 | P2: 0.346 | Q2: 0.866 | R2: 344 | S2: 25 | T2: 100 | U2: 77 | V2: 33 | W2: 16 | X2: 58 | Y2: 1.3275862
A3: 2018 | B3: Regular | C3: 1 | D3: 1 | E3: The Bridgeburners | F3: Fanis | G3: =IF(H3+0.5*J3>6.5,1,0) -> 1 | H3: 7 | I3: 5 | J3: 1 | K3: vs The Others | L3: vs Miggianis | M3: 121 | N3: 0.423 | O3: 38 | P3: 0.336 | Q3: 0.851 | R3: 354 | S3: 17 | T3: 105 | U3: 71 | V3: 20 | W3: 16 | X3: 52 | Y3: 1.3653846
A4: 2018 | B4: Regular | C4: 1 | D4: 2 | E4: Salonika Devils | F4: Fountos | G4: =IF(H4+0.5*J4>6.5,1,0) -> 1 | H4: 10 | I4: 3 | J4: 0 | K4: vs Samarina Dudenbros | L4: vs Sakellariou | M4: 127 | N4: 0.428 | O4: 28 | P4: 0.359 | Q4: 0.8 | R4: 358 | S4: 35 | T4: 110 | U4: 93 | V4: 26 | W4: 11 | X4: 51 | Y4: 1.8235294
A5: 2018 | B5: Regular | C5: 1 | D5: 2 | E5: Samarina Dudenbros | F5: Sakellariou | G5: =IF(H5+0.5*J5>6.5,1,0) -> 0 | H5: 3 | I5: 10 | J5: 0 | K5: vs Salonika Devils | L5: vs Fountos | M5: 106 | N5: 0.379 | O5: 40 | P5: 0.357 | Q5: 0.803 | R5: 301 | S5: 25 | T5: 89 | U5: 69 | V5: 20 | W5: 9 | X5: 47 | Y5: 1.4680851
A6: 2018 | B6: Regular | C6: 1 | D6: 3 | E6: Retsiniakos 21 | F6: Mpousaras | G6: =IF(H6+0.5*J6>6.5,1,0) -> 0 | H6: 2 | I6: 10 | J6: 1 | K6: vs Donkey Rolls | L6: vs Markos | M6: 104 | N6: 0.444 | O6: 20 | P6: 0.333 | Q6: 0.837 | R6: 264 | S6: 33 | T6: 83 | U6: 48 | V6: 17 | W6: 11 | X6: 37 | Y6: 1.2972973
A7: 2018 | B7: Regular | C7: 1 | D7: 3 | E7: Donkey Rolls | F7: Markos | G7: =IF(H7+0.5*J7>6.5,1,0) -> 1 | H7: 10 | I7: 2 | J7: 1 | K7: vs Retsiniakos 21 | L7: vs Mpousaras | M7: 105 | N7: 0.491 | O7: 25 | P7: 0.385 | Q7: 0.907 | R7: 274 | S7: 32 | T7: 97 | U7: 48 | V7: 12 | W7: 16 | X7: 29 | Y7: 1.6551724
A8: 2018 | B8: Regular | C8: 1 | D8: 4 | E8: Karafli SaiTa | F8: Tassos | G8: =IF(H8+0.5*J8>6.5,1,0) -> 1 | H8: 9 | I8: 4 | J8: 0 | K8: vs Steven Adams' Moustache | L8: vs Johnny | M8: 99 | N8: 0.493 | O8: 25 | P8: 0.431 | Q8: 0.877 | R8: 273 | S8: 15 | T8: 73 | U8: 57 | V8: 17 | W8: 9 | X8: 37 | Y8: 1.5405405
A9: 2018 | B9: Regular | C9: 1 | D9: 4 | E9: Steven Adams' Moustache | F9: Johnny | G9: =IF(H9+0.5*J9>6.5,1,0) -> 0 | H9: 4 | I9: 9 | J9: 0 | K9: vs Karafli SaiTa | L9: vs Tassos | M9: 98 | N9: 0.439 | O9: 18 | P9: 0.391 | Q9: 0.62 | R9: 245 | S9: 32 | T9: 91 | U9: 73 | V9: 13 | W9: 11 | X9: 49 | Y9: 1.4897959
A10: 2018 | B10: Regular | C10: 1 | D10: 5 | E10: Drogalo Mountain Goats | F10: Antoniou | G10: =IF(H10+0.5*J10>6.5,1,0) -> 1 | H10: 11 | I10: 2 | J10: 0 | K10: vs Kourayo Vallecano | L10: vs Ziogas/Christof | M10: 113 | N10: 0.448 | O10: 26 | P10: 0.361 | Q10: 0.838 | R10: 319 | S10: 29 | T10: 115 | U10: 57 | V10: 23 | W10: 15 | X10: 38 | Y10: 1.5
A11: 2018 | B11: Regular | C11: 1 | D11: 5 | E11: Kourayo Vallecano | F11: Ziogas/Christof | G11: =IF(H11+0.5*J11>6.5,1,0) -> 0 | H11: 2 | I11: 11 | J11: 0 | K11: vs Drogalo Mountain Goats | L11: vs Antoniou | M11: 95 | N11: 0.401 | O11: 18 | P11: 0.261 | Q11: 0.745 | R11: 281 | S11: 33 | T11: 103 | U11: 73 | V11: 12 | W11: 12 | X11: 49 | Y11: 1.4897959
A12: 2018 | B12: Regular | C12: 1 | D12: 6 | E12: Tsoko Marokana | F12: Lagios | G12: =IF(H12+0.5*J12>6.5,1,0) -> 1 | H12: 11 | I12: 2 | J12: 0 | K12: vs purple fuzzy apache pirates | L12: vs pi/Sotiris | M12: 151 | N12: 0.489 | O12: 28 | P12: 0.308 | Q12: 0.776 | R12: 396 | S12: 32 | T12: 123 | U12: 69 | V12: 29 | W12: 25 | X12: 54 | Y12: 1.2777778
A13: 2018 | B13: Regular | C13: 1 | D13: 6 | E13: purple fuzzy apache pirates | F13: pi/Sotiris | G13: =IF(H13+0.5*J13>6.5,1,0) -> 0 | H13: 2 | I13: 11 | J13: 0 | K13: vs Tsoko Marokana | L13: vs Lagios | M13: 107 | N13: 0.478 | O13: 20 | P13: 0.345 | Q13: 0.711 | R13: 288 | S13: 30 | T13: 82 | U13: 37 | V13: 17 | W13: 14 | X13: 29 | Y13: 1.2758621
... A381: 2018 | B381: Regular | C381: 19 | D381: 190 | E381: Retsiniakos 21 | F381: Mpousaras | G381: =IF(H381+0.5*J381>6.5,1,0) -> 0 | H381: 3 | I381: 10 | J381: 0 | K381: vs Fighting Thaddeus | L381: vs Stavros | M381: 178 | N381: 0.442 | O381: 37 | P381: 0.343 | Q381: 0.765 | R381: 468 | S381: 35 | T381: 118 | U381: 115 | V381: 25 | W381: 20 | X381: 70 | Y381: 1.6428571
A382: 2018 | B382: Playoffs | C382: Quarterfinals | D382: 191 | E382: The Bridgeburners | F382: Fanis | G382: =IF(H382+0.5*J382>6.5,1,0) -> 0 | H382: 6 | I382: 7 | J382: 0 | K382: vs Drogalo Mountain Goats | L382: vs Antoniou | M382: 137 | N382: 0.482 | O382: 38 | P382: 0.418 | Q382: 0.753 | R382: 373 | S382: 32 | T382: 134 | U382: 93 | V382: 36 | W382: 21 | X382: 43 | Y382: 2.1627907
A383: 2018 | B383: Playoffs | C383: Quarterfinals | D383: 191 | E383: Drogalo Mountain Goats | F383: Antoniou | G383: =IF(H383+0.5*J383>6.5,1,0) -> 1 | H383: 7 | I383: 6 | J383: 0 | K383: vs The Bridgeburners | L383: vs Fanis | M383: 147 | N383: 0.473 | O383: 39 | P383: 0.386 | Q383: 0.852 | R383: 385 | S383: 38 | T383: 129 | U383: 81 | V383: 23 | W383: 11 | X383: 37 | Y383: 2.1891892
A384: 2018 | B384: Playoffs | C384: Quarterfinals | D384: 192 | E384: Pachiana NinjaBees | F384: Spiridaus/Oladipas | G384: =IF(H384+0.5*J384>6.5,1,0) -> 1 | H384: 10 | I384: 3 | J384: 0 | K384: vs Salonika Devils | L384: vs Fountos | M384: 171 | N384: 0.46 | O384: 60 | P384: 0.382 | Q384: 0.837 | R384: 474 | S384: 34 | T384: 132 | U384: 113 | V384: 53 | W384: 29 | X384: 54 | Y384: 2.0925926
A385: 2018 | B385: Playoffs | C385: Quarterfinals | D385: 192 | E385: Salonika Devils | F385: Fountos | G385: =IF(H385+0.5*J385>6.5,1,0) -> 0 | H385: 3 | I385: 10 | J385: 0 | K385: vs Pachiana NinjaBees | L385: vs Spiridaus/Oladipas | M385: 152 | N385: 0.431 | O385: 48 | P385: 0.333 | Q385: 0.767 | R385: 421 | S385: 41 | T385: 147 | U385: 63 | V385: 27 | W385: 17 | X385: 47 | Y385: 1.3404255
A386: 2018 | B386: Playoffs | C386: Quarterfinals | D386: 193 | E386: Karafli SaiTa | F386: Tassos | G386: =IF(H386+0.5*J386>6.5,1,0) -> 1 | H386: 11 | I386: 2 | J386: 0 | K386: vs Samarina Dudenbros | L386: vs Sakellariou | M386: 207 | N386: 0.48 | O386: 59 | P386: 0.401 | Q386: 0.657 | R386: 542 | S386: 38 | T386: 139 | U386: 136 | V386: 36 | W386: 33 | X386: 76 | Y386: 1.7894737
A387: 2018 | B387: Playoffs | C387: Quarterfinals | D387: 193 | E387: Samarina Dudenbros | F387: Sakellariou | G387: =IF(H387+0.5*J387>6.5,1,0) -> 0 | H387: 2 | I387: 11 | J387: 0 | K387: vs Karafli SaiTa | L387: vs Tassos | M387: 168 | N387: 0.467 | O387: 45 | P387: 0.357 | Q387: 0.739 | R387: 449 | S387: 31 | T387: 98 | U387: 69 | V387: 26 | W387: 10 | X387: 50 | Y387: 1.38
A388: 2018 | B388: Playoffs | C388: Quarterfinals | D388: 194 | E388: Fighting Thaddeus | F388: Stavros | G388: =IF(H388+0.5*J388>6.5,1,0) -> 0 | H388: 5 | I388: 7 | J388: 1 | K388: vs st.Helens Eruptions | L388: vs Aris | M388: 154 | N388: 0.475 | O388: 46 | P388: 0.43 | Q388: 0.737 | R388: 427 | S388: 37 | T388: 171 | U388: 100 | V388: 28 | W388: 22 | X388: 65 | Y388: 1.5384615
A389: 2018 | B389: Playoffs | C389: Quarterfinals | D389: 194 | E389: st.Helens Eruptions | F389: Aris | G389: =IF(H389+0.5*J389>6.5,1,0) -> 1 | H389: 7 | I389: 5 | J389: 1 | K389: vs Fighting Thaddeus | L389: vs Stavros | M389: 167 | N389: 0.499 | O389: 42 | P389: 0.424 | Q389: 0.802 | R389: 445 | S389: 37 | T389: 129 | U389: 120 | V389: 22 | W389: 20 | X389: 55 | Y389: 2.1818182
A390: 2018 | B390: Playoffs | C390: Semifinals | D390: 195 | E390: Karafli SaiTa | F390: Tassos | G390: =IF(H390+0.5*J390>6.5,1,0) -> 1 | H390: 8 | I390: 5 | J390: 0 | K390: vs Pachiana NinjaBees | L390: vs Spiridaus/Oladipas | M390: 179 | N390: 0.465 | O390: 40 | P390: 0.342 | Q390: 0.674 | R390: 458 | S390: 46 | T390: 121 | U390: 108 | V390: 35 | W390: 31 | X390: 59 | Y390: 1.8305085
A391: 2018 | B391: Playoffs | C391: Semifinals | D391: 195 | E391: Pachiana NinjaBees | F391: Spiridaus/Oladipas | G391: =IF(H391+0.5*J391>6.5,1,0) -> 0 | H391: 5 | I391: 8 | J391: 0 | K391: vs Karafli SaiTa | L391: vs Tassos | M391: 149 | N391: 0.453 | O391: 45 | P391: 0.366 | Q391: 0.833 | R391: 403 | S391: 32 | T391: 152 | U391: 81 | V391: 23 | W391: 18 | X391: 47 | Y391: 1.7234043
A392: 2018 | B392: Playoffs | C392: Semifinals | D392: 196 | E392: st.Helens Eruptions | F392: Aris | G392: =IF(H392+0.5*J392>6.5,1,0) -> 0 | H392: 6 | I392: 7 | J392: 0 | K392: vs Drogalo Mountain Goats | L392: vs Antoniou | M392: 129 | N392: 0.442 | O392: 18 | P392: 0.3 | Q392: 0.693 | R392: 328 | S392: 59 | T392: 121 | U392: 137 | V392: 33 | W392: 20 | X392: 57 | Y392: 2.4035088
A393: 2018 | B393: Playoffs | C393: Semifinals | D393: 196 | E393: Drogalo Mountain Goats | F393: Antoniou | G393: =IF(H393+0.5*J393>6.5,1,0) -> 1 | H393: 7 | I393: 6 | J393: 0 | K393: vs st.Helens Eruptions | L393: vs Aris | M393: 137 | N393: 0.495 | O393: 33 | P393: 0.5 | Q393: 0.824 | R393: 368 | S393: 35 | T393: 106 | U393: 77 | V393: 26 | W393: 11 | X393: 47 | Y393: 1.6382979
... A397: 2018 | B397: Playoffs | C397: 3rd place | D397: 198 | E397: Pachiana NinjaBees | F397: Spiridaus/Oladipas | G397: =IF(H397+0.5*J397>6.5,1,0) -> 1 | H397: 8 | I397: 5 | J397: 0 | K397: vs st.Helens Eruptions | L397: vs Aris | M397: 179 | N397: 0.489 | O397: 71 | P397: 0.461 | Q397: 0.814 | R397: 499 | S397: 24 | T397: 148 | U397: 92 | V397: 25 | W397: 20 | X397: 49 | Y397: 1.877551
A398: 2019 | B398: Regular | C398: 1 | D398: 1 | E398: The Bridgeburners | F398: Fanis | G398: =IF(H398+0.5*J398>6.5,1,0) -> 1 | H398: 9 | I398: 4 | J398: 0 | K398: vs The Others | L398: vs Miggianis | M398: 127 | N398: 0.506 | O398: 48 | P398: 0.466 | Q398: 0.761 | R398: 337 | S398: 26 | T398: 108 | U398: 76 | V398: 23 | W398: 10 | X398: 41 | Y398: 1.8536585
A399: 2019 | B399: Regular | C399: 1 | D399: 1 | E399: The Others | F399: Miggianis | G399: =IF(H399+0.5*J399>6.5,1,0) -> 0 | H399: 4 | I399: 9 | J399: 0 | K399: vs The Bridgeburners | L399: vs Fanis | M399: 81 | N399: 0.438 | O399: 27 | P399: 0.409 | Q399: 0.804 | R399: 234 | S399: 14 | T399: 75 | U399: 60 | V399: 18 | W399: 12 | X399: 31 | Y399: 1.9354839
A400: 2019 | B400: Regular | C400: 1 | D400: 2 | E400: Salonika Devils | F400: Fountos | G400: =IF(H400+0.5*J400>6.5,1,0) -> 1 | H400: 9 | I400: 4 | J400: 0 | K400: vs Samarina Dudenbros | L400: vs Sakellariou | M400: 153 | N400: 0.502 | O400: 40 | P400: 0.476 | Q400: 0.733 | R400: 409 | S400: 43 | T400: 83 | U400: 61 | V400: 26 | W400: 12 | X400: 27 | Y400: 2.2592593
A401: 2019 | B401: Regular | C401: 1 | D401: 2 | E401: Samarina Dudenbros | F401: Sakellariou | G401: =IF(H401+0.5*J401>6.5,1,0) -> 0 | H401: 4 | I401: 9 | J401: 0 | K401: vs Salonika Devils | L401: vs Fountos | M401: 125 | N401: 0.406 | O401: 31 | P401: 0.307 | Q401: 0.877 | R401: 352 | S401: 27 | T401: 122 | U401: 72 | V401: 19 | W401: 13 | X401: 47 | Y401: 1.5319149
A402: 2019 | B402: Regular | C402: 1 | D402: 3 | E402: Donkey Rolls | F402: Markos | G402: =IF(H402+0.5*J402>6.5,1,0) -> 1 | H402: 9 | I402: 4 | J402: 0 | K402: vs Retsiniakos 21 | L402: vs Mpousaras | M402: 137 | N402: 0.431 | O402: 42 | P402: 0.353 | Q402: 0.772 | R402: 377 | S402: 28 | T402: 109 | U402: 78 | V402: 16 | W402: 18 | X402: 37 | Y402: 2.1081081
A403: 2019 | B403: Regular | C403: 1 | D403: 3 | E403: Retsiniakos 21 | F403: Mpousaras | G403: =IF(H403+0.5*J403>6.5,1,0) -> 0 | H403: 4 | I403: 9 | J403: 0 | K403: vs Donkey Rolls | L403: vs Markos | M403: 103 | N403: 0.436 | O403: 24 | P403: 0.329 | Q403: 0.813 | R403: 269 | S403: 31 | T403: 80 | U403: 64 | V403: 14 | W403: 8 | X403: 31 | Y403: 2.0645161
A404: 2019 | B404: Regular | C404: 1 | D404: 4 | E404: Karafli SaiTa | F404: Tassos | G404: =IF(H404+0.5*J404>6.5,1,0) -> 0 | H404: 5 | I404: 8 | J404: 0 | K404: vs Steven Adams' Moustache | L404: vs Johnny | M404: 161 | N404: 0.436 | O404: 37 | P404: 0.291 | Q404: 0.75 | R404: 434 | S404: 38 | T404: 123 | U404: 70 | V404: 33 | W404: 20 | X404: 49 | Y404: 1.4285714
A405: 2019 | B405: Regular | C405: 1 | D405: 4 | E405: Steven Adams' Moustache | F405: Johnny | G405: =IF(H405+0.5*J405>6.5,1,0) -> 1 | H405: 8 | I405: 5 | J405: 0 | K405: vs Karafli SaiTa | L405: vs Tassos | M405: 136 | N405: 0.504 | O405: 24 | P405: 0.333 | Q405: 0.792 | R405: 391 | S405: 51 | T405: 124 | U405: 92 | V405: 24 | W405: 21 | X405: 52 | Y405: 1.7692308
A406: 2019 | B406: Regular | C406: 1 | D406: 5 | E406: Kourayo Vallecano | F406: Ziogas/Christof | G406: =IF(H406+0.5*J406>6.5,1,0) -> 1 | H406: 7 | I406: 6 | J406: 0 | K406: vs Drogalo Mountain Goats | L406: vs Antoniou | M406: 121 | N406: 0.451 | O406: 25 | P406: 0.301 | Q406: 0.692 | R406: 330 | S406: 27 | T406: 127 | U406: 53 | V406: 25 | W406: 24 | X406: 56 | Y406: 0.94642857
A407: 2019 | B407: Regular | C407: 1 | D407: 5 | E407: Drogalo Mountain Goats | F407: Antoniou | G407: =IF(H407+0.5*J407>6.5,1,0) -> 0 | H407: 6 | I407: 7 | J407: 0 | K407: vs Kourayo Vallecano | L407: vs Ziogas/Christof | M407: 100 | N407: 0.463 | O407: 33 | P407: 0.418 | Q407: 0.833 | R407: 273 | S407: 24 | T407: 85 | U407: 51 | V407: 13 | W407: 16 | X407: 39 | Y407: 1.3076923
A408: 2019 | B408: Regular | C408: 1 | D408: 6 | E408: purple fuzzy apache pirates | F408: pi/Sotiris | G408: =IF(H408+0.5*J408>6.5,1,0) -> 1 | H408: 9 | I408: 4 | J408: 0 | K408: vs Tsoko Marokana | L408: vs Lagios | M408: 148 | N408: 0.521 | O408: 34 | P408: 0.374 | Q408: 0.827 | R408: 392 | S408: 24 | T408: 129 | U408: 54 | V408: 17 | W408: 21 | X408: 57 | Y408: 0.94736842
A409: 2019 | B409: Regular | C409: 1 | D409: 6 | E409: Tsoko Marokana | F409: Lagios | G409: =IF(H409+0.5*J409>6.5,1,0) -> 0 | H409: 4 | I409: 9 | J409: 0 | K409: vs purple fuzzy apache pirates | L409: vs pi/Sotiris | M409: 116 | N409: 0.425 | O409: 26 | P409: 0.302 | Q409: 0.77 | R409: 325 | S409: 46 | T409: 111 | U409: 95 | V409: 14 | W409: 9 | X409: 55 | Y409: 1.7272727
... A777: 2019 | B777: Regular | C777: 19 | D777: 190 | E777: Fighting Thaddeus | F777: Stavros | G777: =IF(H777+0.5*J777>6.5,1,0) -> 1 | H777: 8 | I777: 5 | J777: 0 | K777: vs Retsiniakos 21 | L777: vs Mpousaras | M777: 180 | N777: 0.446 | O777: 45 | P777: 0.319 | Q777: 0.86 | R777: 534 | S777: 39 | T777: 120 | U777: 128 | V777: 29 | W777: 19 | X777: 60 | Y777: 2.13
...

Sheet Clean data
A1: Year | B1: Regular/ Playoffs | C1: Period | D1: Match No | E1: Team | F1: Manager | G1: Games Won | H1: W | I1: L | J1: D | K1: vs Opponent | L1: vs Manager | M1: FGM | N1: FG% | O1: 3PM | P1: 3P% | Q1: FT% | R1: PTS | S1: OREB | T1: DREB | U1: AST | V1: STL | W1: BLK | X1: TO | Y1: A/TO
A2: 2026 | B2: Regular | C2: 1 | D2: 1 | E2: =+'Raw data'!A5 -> Kourayo Vallecano | F2: =VLOOKUP(E2,Data!$E$2626:$F$2645,2,FALSE) -> Ziogas/Christof | H2: =+'Raw data'!A26 -> 6 | I2: =+'Raw data'!B26 -> 7 | J2: =+'Raw data'!C26 -> 0 | M2: =+'Raw data'!E26 -> 127 | N2: =+'Raw data'!F26 -> 0.464 | O2: =+'Raw data'!G26 -> 30 | P2: =+'Raw data'!H26 -> 0.291 | Q2: =+'Raw data'!I26 -> 0.743 | R2: =+'Raw data'!J26 -> 359 | S2: =+'Raw data'!K26 -> 46 | T2: =+'Raw data'!L26 -> 113 | ... Y2: =+'Raw data'!Q26 -> 2.65
A3: 2025 | B3: Regular | C3: 1 | D3: 1 | E3: =+'Raw data'!A6 -> LRBP PR3DATORS | F3: =VLOOKUP(E3,Data!$E$2626:$F$2645,2,FALSE) -> Lafa | H3: =+'Raw data'!A27 -> 7 | I3: =+'Raw data'!B27 -> 6 | J3: =+'Raw data'!C27 -> 0 | M3: =+'Raw data'!E27 -> 171 | N3: =+'Raw data'!F27 -> 0.46 | O3: =+'Raw data'!G27 -> 37 | P3: =+'Raw data'!H27 -> 0.291 | Q3: =+'Raw data'!I27 -> 0.816 | R3: =+'Raw data'!J27 -> 508 | S3: =+'Raw data'!K27 -> 25 | T3: =+'Raw data'!L27 -> 132 | ... Y3: =+'Raw data'!Q27 -> 1.17
A4: 2025 | B4: Regular | C4: 1 | D4: =+D2+1 -> 2 | E4: =+'Raw data'!A7 -> Xanthi Ducks 🦆 | F4: =VLOOKUP(E4,Data!$E$2626:$F$2645,2,FALSE) -> Kotakis | H4: =+'Raw data'!A28 -> 3 | I4: =+'Raw data'!B28 -> 10 | J4: =+'Raw data'!C28 -> 0 | M4: =+'Raw data'!E28 -> 85 | N4: =+'Raw data'!F28 -> 0.436 | O4: =+'Raw data'!G28 -> 31 | P4: =+'Raw data'!H28 -> 0.365 | Q4: =+'Raw data'!I28 -> 0.766 | R4: =+'Raw data'!J28 -> 250 | S4: =+'Raw data'!K28 -> 38 | T4: =+'Raw data'!L28 -> 85 | ... Y4: =+'Raw data'!Q28 -> 1.72
A5: 2025 | B5: Regular | C5: 1 | D5: =+D3+1 -> 2 | E5: =+'Raw data'!A8 -> The Bridgeburners | F5: =VLOOKUP(E5,Data!$E$2626:$F$2645,2,FALSE) -> Fanis | H5: =+'Raw data'!A29 -> 10 | I5: =+'Raw data'!B29 -> 3 | J5: =+'Raw data'!C29 -> 0 | M5: =+'Raw data'!E29 -> 165 | N5: =+'Raw data'!F29 -> 0.493 | O5: =+'Raw data'!G29 -> 54 | P5: =+'Raw data'!H29 -> 0.394 | Q5: =+'Raw data'!I29 -> 0.817 | R5: =+'Raw data'!J29 -> 473 | S5: =+'Raw data'!K29 -> 24 | T5: =+'Raw data'!L29 -> 109 | ... Y5: =+'Raw data'!Q29 -> 1.64
A6: 2025 | B6: Regular | C6: 1 | D6: =+D4+1 -> 3 | E6: =+'Raw data'!A9 -> The Guns | F6: =VLOOKUP(E6,Data!$E$2626:$F$2645,2,FALSE) -> Vasilis | H6: =+'Raw data'!A30 -> 10 | I6: =+'Raw data'!B30 -> 3 | J6: =+'Raw data'!C30 -> 0 | M6: =+'Raw data'!E30 -> 165 | N6: =+'Raw data'!F30 -> 0.473 | O6: =+'Raw data'!G30 -> 38 | P6: =+'Raw data'!H30 -> 0.288 | Q6: =+'Raw data'!I30 -> 0.826 | R6: =+'Raw data'!J30 -> 477 | S6: =+'Raw data'!K30 -> 41 | T6: =+'Raw data'!L30 -> 122 | ... Y6: =+'Raw data'!Q30 -> 1.93
A7: 2025 | B7: Regular | C7: 1 | D7: =+D5+1 -> 3 | E7: =+'Raw data'!A10 -> Heraklion Snakes | F7: =VLOOKUP(E7,Data!$E$2626:$F$2645,2,FALSE) -> Dimitris | H7: =+'Raw data'!A31 -> 3 | I7: =+'Raw data'!B31 -> 10 | J7: =+'Raw data'!C31 -> 0 | M7: =+'Raw data'!E31 -> 68 | N7: =+'Raw data'!F31 -> 0.456 | O7: =+'Raw data'!G31 -> 19 | P7: =+'Raw data'!H31 -> 0.345 | Q7: =+'Raw data'!I31 -> 0.87 | R7: =+'Raw data'!J31 -> 195 | S7: =+'Raw data'!K31 -> 19 | T7: =+'Raw data'!L31 -> 54 | ... Y7: =+'Raw data'!Q31 -> 1.21
A8: 2025 | B8: Regular | C8: 1 | D8: =+D6+1 -> 4 | E8: =+'Raw data'!A11 -> Tsarlatans | F8: =VLOOKUP(E8,Data!$E$2626:$F$2645,2,FALSE) -> Tzokos | H8: =+'Raw data'!A32 -> 5 | I8: =+'Raw data'!B32 -> 8 | J8: =+'Raw data'!C32 -> 0 | M8: =+'Raw data'!E32 -> 130 | N8: =+'Raw data'!F32 -> 0.455 | O8: =+'Raw data'!G32 -> 24 | P8: =+'Raw data'!H32 -> 0.293 | Q8: =+'Raw data'!I32 -> 0.839 | R8: =+'Raw data'!J32 -> 357 | S8: =+'Raw data'!K32 -> 33 | T8: =+'Raw data'!L32 -> 107 | ... Y8: =+'Raw data'!Q32 -> 1.53
A9: 2025 | B9: Regular | C9: 1 | D9: =+D7+1 -> 4 | E9: =+'Raw data'!A12 -> Guruuu 🐐🐐🐐 | F9: =VLOOKUP(E9,Data!$E$2626:$F$2645,2,FALSE) -> Guru | H9: =+'Raw data'!A33 -> 8 | I9: =+'Raw data'!B33 -> 5 | J9: =+'Raw data'!C33 -> 0 | M9: =+'Raw data'!E33 -> 125 | N9: =+'Raw data'!F33 -> 0.448 | O9: =+'Raw data'!G33 -> 44 | P9: =+'Raw data'!H33 -> 0.361 | Q9: =+'Raw data'!I33 -> 0.765 | R9: =+'Raw data'!J33 -> 398 | S9: =+'Raw data'!K33 -> 36 | T9: =+'Raw data'!L33 -> 83 | ... Y9: =+'Raw data'!Q33 -> 3.19
A10: 2025 | B10: Regular | C10: 1 | D10: =+D8+1 -> 5 | E10: =+'Raw data'!A13 -> Hércules Pals | F10: =VLOOKUP(E10,Data!$E$2626:$F$2645,2,FALSE) -> #N/A | H10: =+'Raw data'!A34 -> 3 | I10: =+'Raw data'!B34 -> 10 | J10: =+'Raw data'!C34 -> 0 | M10: =+'Raw data'!E34 -> 66 | N10: =+'Raw data'!F34 -> 0.379 | O10: =+'Raw data'!G34 -> 32 | P10: =+'Raw data'!H34 -> 0.39 | Q10: =+'Raw data'!I34 -> 0.822 | R10: =+'Raw data'!J34 -> 201 | S10: =+'Raw data'!K34 -> 30 | T10: =+'Raw data'!L34 -> 78 | ... Y10: =+'Raw data'!Q34 -> 2
